<?xml version="1.0" encoding="UTF-8"?>
<testsuites>
	<testsuite name="tests.PostTestCase-20200529174320" tests="12" file="tests.py" time="0.092" timestamp="2020-05-29T17:43:20" failures="9" errors="0" skipped="0">
		<testcase classname="tests.PostTestCase" name="test_task12_make_migrations" time="0.010" timestamp="2020-05-29T17:43:20" file="module4\tests.py" line="282">
			<system-out><![CDATA[]]></system-out>
			<system-err><![CDATA[]]></system-err>
		</testcase>
		<testcase classname="tests.PostTestCase" name="test_task1_tag_model_exists" time="0.004" timestamp="2020-05-29T17:43:20" file="module4\tests.py" line="114">
			<!-- Add Tag model to models.py
            class Tag(models.Model):
                name = models.CharField(max_length=50, unique=True) -->
			<system-out><![CDATA[]]></system-out>
			<system-err><![CDATA[]]></system-err>
		</testcase>
		<testcase classname="tests.PostTestCase" name="test_task3_str_exists" time="0.002" timestamp="2020-05-29T17:43:20" file="module4\tests.py" line="132">
			<system-out><![CDATA[]]></system-out>
			<system-err><![CDATA[]]></system-err>
		</testcase>
		<testcase classname="tests.PostTestCase" name="test_task10_uncomment_templates" time="0.053" timestamp="2020-05-29T17:43:20" file="module4\tests.py" line="246">
			<failure type="AssertionError" message="There is still a `{% comment %}` tag in `mainapp/templates/mainapp/snippet_post_list.html`"><![CDATA[Traceback (most recent call last):
  File "D:\pluralsight_project\python-django-models-authentication\module4\tests.py", line 255, in test_task10_uncomment_templates
    self.assertTrue(not comment_found, msg="There is still a `{% comment %}` tag in `" + filename + "`")
  File "D:\pluralsight_project\python-django-models-authentication\support\SimplerTestCase.py", line 12, in assertTrue
    self.fail(msg or (str(expr) + "is not True"))
AssertionError: There is still a `{% comment %}` tag in `mainapp/templates/mainapp/snippet_post_list.html`
]]></failure>
			<system-out><![CDATA[]]></system-out>
			<system-err><![CDATA[]]></system-err>
		</testcase>
		<testcase classname="tests.PostTestCase" name="test_task11_admin_register_tag" time="0.005" timestamp="2020-05-29T17:43:20" file="module4\tests.py" line="258">
			<failure type="AssertionError" message="Did you import `Tag`?"><![CDATA[Traceback (most recent call last):
  File "D:\pluralsight_project\python-django-models-authentication\module4\tests.py", line 279, in test_task11_admin_register_tag
    self.assertTrue(import_Tag_found, msg="Did you import `Tag`?")
  File "D:\pluralsight_project\python-django-models-authentication\support\SimplerTestCase.py", line 12, in assertTrue
    self.fail(msg or (str(expr) + "is not True"))
AssertionError: Did you import `Tag`?
]]></failure>
			<system-out><![CDATA[]]></system-out>
			<system-err><![CDATA[]]></system-err>
		</testcase>
		<testcase classname="tests.PostTestCase" name="test_task2_clean_method_exists" time="0.003" timestamp="2020-05-29T17:43:20" file="module4\tests.py" line="125">
			<!--Add clean method to sanitize input.-->
			<failure type="AssertionError" message="Did you implement the `clean` method in the `Tag` model class?"><![CDATA[Traceback (most recent call last):
  File "D:\pluralsight_project\python-django-models-authentication\module4\tests.py", line 129, in test_task2_clean_method_exists
    self.assertTrue(self.clean_method_found, msg="Did you implement the `clean` method in the `Tag` model class?")
  File "D:\pluralsight_project\python-django-models-authentication\support\SimplerTestCase.py", line 12, in assertTrue
    self.fail(msg or (str(expr) + "is not True"))
AssertionError: Did you implement the `clean` method in the `Tag` model class?
]]></failure>
			<system-out><![CDATA[]]></system-out>
			<system-err><![CDATA[]]></system-err>
		</testcase>
		<testcase classname="tests.PostTestCase" name="test_task4_many_to_many_exists" time="0.004" timestamp="2020-05-29T17:43:20" file="module4\tests.py" line="136">
			<failure type="AssertionError" message="Did you add the `name` field?"><![CDATA[Traceback (most recent call last):
  File "D:\pluralsight_project\python-django-models-authentication\module4\tests.py", line 138, in test_task4_many_to_many_exists
    self.assertTrue(self.tags_field_found, msg="Did you add the `name` field?")
  File "D:\pluralsight_project\python-django-models-authentication\support\SimplerTestCase.py", line 12, in assertTrue
    self.fail(msg or (str(expr) + "is not True"))
AssertionError: Did you add the `name` field?
]]></failure>
			<system-out><![CDATA[]]></system-out>
			<system-err><![CDATA[]]></system-err>
		</testcase>
		<testcase classname="tests.PostTestCase" name="test_task5_tag_view" time="0.003" timestamp="2020-05-29T17:43:20" file="module4\tests.py" line="192">
			<failure type="AssertionError" message="Did you create the `tag_post` function?"><![CDATA[Traceback (most recent call last):
  File "D:\pluralsight_project\python-django-models-authentication\module4\tests.py", line 195, in test_task5_tag_view
    self.assertTrue(self.tag_view_found, msg="Did you create the `tag_post` function?")
  File "D:\pluralsight_project\python-django-models-authentication\support\SimplerTestCase.py", line 12, in assertTrue
    self.fail(msg or (str(expr) + "is not True"))
AssertionError: Did you create the `tag_post` function?
]]></failure>
			<system-out><![CDATA[]]></system-out>
			<system-err><![CDATA[]]></system-err>
		</testcase>
		<testcase classname="tests.PostTestCase" name="test_task6_tag_view_title" time="0.003" timestamp="2020-05-29T17:43:20" file="module4\tests.py" line="198">
			<failure type="AssertionError" message="Did you lowercase `name` in the `tag_post` method?"><![CDATA[Traceback (most recent call last):
  File "D:\pluralsight_project\python-django-models-authentication\module4\tests.py", line 200, in test_task6_tag_view_title
    self.assertTrue(self.tag_view_name_assign_found, msg="Did you lowercase `name` in the `tag_post` method?")
  File "D:\pluralsight_project\python-django-models-authentication\support\SimplerTestCase.py", line 12, in assertTrue
    self.fail(msg or (str(expr) + "is not True"))
AssertionError: Did you lowercase `name` in the `tag_post` method?
]]></failure>
			<system-out><![CDATA[]]></system-out>
			<system-err><![CDATA[]]></system-err>
		</testcase>
		<testcase classname="tests.PostTestCase" name="test_task7_tag_view_find_posts" time="0.002" timestamp="2020-05-29T17:43:20" file="module4\tests.py" line="203">
			<failure type="AssertionError" message="Did you set `tag` to `get_object_or_404`'s result?"><![CDATA[Traceback (most recent call last):
  File "D:\pluralsight_project\python-django-models-authentication\module4\tests.py", line 206, in test_task7_tag_view_find_posts
    self.assertTrue(self.tag_view_get_object_found, msg="Did you set `tag` to `get_object_or_404`'s result?")
  File "D:\pluralsight_project\python-django-models-authentication\support\SimplerTestCase.py", line 12, in assertTrue
    self.fail(msg or (str(expr) + "is not True"))
AssertionError: Did you set `tag` to `get_object_or_404`'s result?
]]></failure>
			<system-out><![CDATA[]]></system-out>
			<system-err><![CDATA[]]></system-err>
		</testcase>
		<testcase classname="tests.PostTestCase" name="test_task8_add_tag_url" time="0.002" timestamp="2020-05-29T17:43:20" file="module4\tests.py" line="209">
			<failure type="AssertionError" message="Did you add the tag path to urls.py with the route `'tag/&lt;str:name&gt;'`?"><![CDATA[Traceback (most recent call last):
  File "D:\pluralsight_project\python-django-models-authentication\module4\tests.py", line 212, in test_task8_add_tag_url
    self.assertTrue(self.tag_posts_route_found, msg="Did you add the tag path to urls.py with the route `'tag/<str:name>'`?")
  File "D:\pluralsight_project\python-django-models-authentication\support\SimplerTestCase.py", line 12, in assertTrue
    self.fail(msg or (str(expr) + "is not True"))
AssertionError: Did you add the tag path to urls.py with the route `'tag/<str:name>'`?
]]></failure>
			<system-out><![CDATA[]]></system-out>
			<system-err><![CDATA[]]></system-err>
		</testcase>
		<testcase classname="tests.PostTestCase" name="test_task9_url_reverser" time="0.001" timestamp="2020-05-29T17:43:20" file="module4\tests.py" line="236">
			<failure type="AssertionError" message="The method `get_absolute_url()` does not exist in the BlogPost model."><![CDATA[Traceback (most recent call last):
  File "D:\pluralsight_project\python-django-models-authentication\module4\tests.py", line 240, in test_task9_url_reverser
    self.assertTrue(self.get_absolute_url_found, msg="The method `get_absolute_url()` does not exist in the BlogPost model.")
  File "D:\pluralsight_project\python-django-models-authentication\support\SimplerTestCase.py", line 12, in assertTrue
    self.fail(msg or (str(expr) + "is not True"))
AssertionError: The method `get_absolute_url()` does not exist in the BlogPost model.
]]></failure>
			<system-out><![CDATA[]]></system-out>
			<system-err><![CDATA[]]></system-err>
		</testcase>
	</testsuite>
</testsuites>
